<?xml version="1.0" ?>
<robot name="lion_claw" xmlns:xacro="http://www.ros.org/wiki/xacro">

<xacro:include filename="$(find lion_claw_description)/urdf/materials.xacro" />
<xacro:include filename="$(find lion_claw_description)/urdf/lion_claw.trans" />
<xacro:include filename="$(find lion_claw_description)/urdf/lion_claw.gazebo" />
<link name="base_link">
  <inertial>
    <origin xyz="-3.5038751038095783e-15 1.138759408738113e-13 -0.02184941545044436" rpy="0 0 0"/>
    <mass value="0.18656872987375012"/>
    <inertia ixx="5e-05" iyy="3.7e-05" izz="7.3e-05" ixy="0.0" iyz="0.0" ixz="-0.0"/>
  </inertial>
  <visual>
    <origin xyz="0 0 0" rpy="0 0 0"/>
    <geometry>
      <mesh filename="package://lion_claw_description/meshes/base_link.stl" scale="0.001 0.001 0.001"/>
    </geometry>
    <material name="silver"/>
  </visual>
  <collision>
    <origin xyz="0 0 0" rpy="0 0 0"/>
    <geometry>
      <mesh filename="package://lion_claw_description/meshes/base_link.stl" scale="0.001 0.001 0.001"/>
    </geometry>
  </collision>
</link>

<link name="face_bolt_1">
  <inertial>
    <origin xyz="-2.3864795246743213e-05 3.1026942694426355e-06 0.019193370676955403" rpy="0 0 0"/>
    <mass value="0.02499449229797251"/>
    <inertia ixx="3e-06" iyy="3e-06" izz="1e-06" ixy="0.0" iyz="-0.0" ixz="0.0"/>
  </inertial>
  <visual>
    <origin xyz="-0.0 -0.0 0.028346" rpy="0 0 0"/>
    <geometry>
      <mesh filename="package://lion_claw_description/meshes/face_bolt_1.stl" scale="0.001 0.001 0.001"/>
    </geometry>
    <material name="silver"/>
  </visual>
  <collision>
    <origin xyz="-0.0 -0.0 0.028346" rpy="0 0 0"/>
    <geometry>
      <mesh filename="package://lion_claw_description/meshes/face_bolt_1.stl" scale="0.001 0.001 0.001"/>
    </geometry>
  </collision>
</link>

<link name="fusion_wheel_1">
  <inertial>
    <origin xyz="1.1768987917548657e-09 -7.615916786107846e-12 -0.008721304375586759" rpy="0 0 0"/>
    <mass value="0.3199627508858946"/>
    <inertia ixx="9.2e-05" iyy="9.2e-05" izz="0.000173" ixy="0.0" iyz="0.0" ixz="-0.0"/>
  </inertial>
  <visual>
    <origin xyz="-0.0 -0.0 -0.001484" rpy="0 0 0"/>
    <geometry>
      <mesh filename="package://lion_claw_description/meshes/fusion_wheel_1.stl" scale="0.001 0.001 0.001"/>
    </geometry>
    <material name="silver"/>
  </visual>
  <collision>
    <origin xyz="-0.0 -0.0 -0.001484" rpy="0 0 0"/>
    <geometry>
      <mesh filename="package://lion_claw_description/meshes/fusion_wheel_1.stl" scale="0.001 0.001 0.001"/>
    </geometry>
  </collision>
</link>

<link name="claw_1_1">
  <inertial>
    <origin xyz="-0.009406159990673228 -1.8952289329747e-18 -0.00042267152208199515" rpy="0 0 0"/>
    <mass value="0.009197042733648284"/>
    <inertia ixx="0.0" iyy="1e-06" izz="1e-06" ixy="-0.0" iyz="0.0" ixz="-0.0"/>
  </inertial>
  <visual>
    <origin xyz="0.007 0.0 0.01915" rpy="0 0 0"/>
    <geometry>
      <mesh filename="package://lion_claw_description/meshes/claw_1_1.stl" scale="0.001 0.001 0.001"/>
    </geometry>
    <material name="silver"/>
  </visual>
  <collision>
    <origin xyz="0.007 0.0 0.01915" rpy="0 0 0"/>
    <geometry>
      <mesh filename="package://lion_claw_description/meshes/claw_1_1.stl" scale="0.001 0.001 0.001"/>
    </geometry>
  </collision>
</link>

<link name="claw_2_1">
  <inertial>
    <origin xyz="0.009406159990673228 -1.8952289329747e-18 -0.00042267152208199515" rpy="0 0 0"/>
    <mass value="0.009197042733648284"/>
    <inertia ixx="0.0" iyy="1e-06" izz="1e-06" ixy="-0.0" iyz="0.0" ixz="0.0"/>
  </inertial>
  <visual>
    <origin xyz="-0.007 0.0 0.01915" rpy="0 0 0"/>
    <geometry>
      <mesh filename="package://lion_claw_description/meshes/claw_2_1.stl" scale="0.001 0.001 0.001"/>
    </geometry>
    <material name="silver"/>
  </visual>
  <collision>
    <origin xyz="-0.007 0.0 0.01915" rpy="0 0 0"/>
    <geometry>
      <mesh filename="package://lion_claw_description/meshes/claw_2_1.stl" scale="0.001 0.001 0.001"/>
    </geometry>
  </collision>
</link>

<joint name="Rigid10" type="fixed">
  <origin xyz="0.0 0.0 -0.028346" rpy="0 0 0"/>
  <parent link="base_link"/>
  <child link="face_bolt_1"/>
</joint>

<joint name="Rigid11" type="fixed">
  <origin xyz="0.0 0.0 0.02983" rpy="0 0 0"/>
  <parent link="face_bolt_1"/>
  <child link="fusion_wheel_1"/>
</joint>

<joint name="Slider15" type="prismatic">
  <origin xyz="-0.007 0.0 -0.01915" rpy="0 0 0"/>
  <parent link="base_link"/>
  <child link="claw_1_1"/>
  <axis xyz="-1.0 -0.0 0.0"/>
  <limit upper="0.015" lower="0.0" effort="100" velocity="100"/>
</joint>

<joint name="Slider16" type="prismatic">
  <origin xyz="0.007 0.0 -0.01915" rpy="0 0 0"/>
  <parent link="base_link"/>
  <child link="claw_2_1"/>
  <axis xyz="1.0 0.0 0.0"/>
  <limit upper="0.015" lower="0.0" effort="100" velocity="100"/>
</joint>

</robot>
